<?xml version="1.0" encoding="UTF-8"?>
<testng-results skipped="2" failed="0" total="2" passed="0">
  <reporter-output>
  </reporter-output>
  <suite name="Default suite" duration-ms="11846" started-at="2020-02-14T06:07:56Z" finished-at="2020-02-14T06:08:08Z">
    <groups>
    </groups>
    <test name="Default test" duration-ms="11846" started-at="2020-02-14T06:07:56Z" finished-at="2020-02-14T06:08:08Z">
      <class name="testcases.LoginTestWithDataProvider">
        <test-method status="PASS" signature="setupReport()[pri:0, instance:testcases.LoginTestWithDataProvider@3532ec19]" name="setupReport" is-config="true" duration-ms="248" started-at="2020-02-14T01:07:56Z" finished-at="2020-02-14T01:07:56Z">
          <reporter-output>
          </reporter-output>
        </test-method> <!-- setupReport -->
        <test-method status="PASS" signature="setupBrowser()[pri:0, instance:testcases.LoginTestWithDataProvider@3532ec19]" name="setupBrowser" is-config="true" duration-ms="11011" started-at="2020-02-14T01:07:56Z" finished-at="2020-02-14T01:08:07Z">
          <reporter-output>
          </reporter-output>
        </test-method> <!-- setupBrowser -->
        <test-method status="SKIP" signature="loginToAP(java.lang.String, java.lang.String)[pri:0, instance:testcases.LoginTestWithDataProvider@3532ec19]" name="loginToAP" duration-ms="0" started-at="2020-02-14T01:08:07Z" data-provider="Login" finished-at="2020-02-14T01:08:07Z">
          <exception class="org.testng.TestNGException">
            <message>
              <![CDATA[
Method public void testcases.LoginTestWithDataProvider.loginToAP(java.lang.String,java.lang.String) requires a @DataProvider named : Login]]>
            </message>
            <full-stacktrace>
              <![CDATA[org.testng.TestNGException: 
Method public void testcases.LoginTestWithDataProvider.loginToAP(java.lang.String,java.lang.String) requires a @DataProvider named : Login
	at org.testng.internal.Parameters.findDataProvider(Parameters.java:263)
	at org.testng.internal.Parameters.handleParameters(Parameters.java:419)
	at org.testng.internal.Invoker.handleParameters(Invoker.java:1274)
	at org.testng.internal.Invoker.createParameters(Invoker.java:989)
	at org.testng.internal.Invoker.invokeTestMethods(Invoker.java:1079)
	at org.testng.internal.TestMethodWorker.invokeTestMethods(TestMethodWorker.java:129)
	at org.testng.internal.TestMethodWorker.run(TestMethodWorker.java:112)
	at org.testng.TestRunner.privateRun(TestRunner.java:782)
	at org.testng.TestRunner.run(TestRunner.java:632)
	at org.testng.SuiteRunner.runTest(SuiteRunner.java:366)
	at org.testng.SuiteRunner.runSequentially(SuiteRunner.java:361)
	at org.testng.SuiteRunner.privateRun(SuiteRunner.java:319)
	at org.testng.SuiteRunner.run(SuiteRunner.java:268)
	at org.testng.SuiteRunnerWorker.runSuite(SuiteRunnerWorker.java:52)
	at org.testng.SuiteRunnerWorker.run(SuiteRunnerWorker.java:86)
	at org.testng.TestNG.runSuitesSequentially(TestNG.java:1244)
	at org.testng.TestNG.runSuitesLocally(TestNG.java:1169)
	at org.testng.TestNG.run(TestNG.java:1064)
	at org.testng.remote.AbstractRemoteTestNG.run(AbstractRemoteTestNG.java:132)
	at org.testng.remote.RemoteTestNG.initAndRun(RemoteTestNG.java:236)
	at org.testng.remote.RemoteTestNG.main(RemoteTestNG.java:81)
]]>
            </full-stacktrace>
          </exception> <!-- org.testng.TestNGException -->
          <reporter-output>
          </reporter-output>
        </test-method> <!-- loginToAP -->
        <test-method status="SKIP" signature="userManagement(java.lang.String, java.lang.String, java.lang.String, java.lang.String, java.lang.String, java.lang.String)[pri:0, instance:testcases.LoginTestWithDataProvider@3532ec19]" name="userManagement" duration-ms="0" started-at="2020-02-14T01:08:07Z" data-provider="userManagement" finished-at="2020-02-14T01:08:07Z">
          <exception class="java.lang.RuntimeException">
            <message>
              <![CDATA[java.lang.NullPointerException]]>
            </message>
            <full-stacktrace>
              <![CDATA[java.lang.RuntimeException: java.lang.NullPointerException
	at org.testng.internal.MethodInvocationHelper.invokeDataProvider(MethodInvocationHelper.java:163)
	at org.testng.internal.Parameters.handleParameters(Parameters.java:430)
	at org.testng.internal.Invoker.handleParameters(Invoker.java:1274)
	at org.testng.internal.Invoker.createParameters(Invoker.java:989)
	at org.testng.internal.Invoker.invokeTestMethods(Invoker.java:1079)
	at org.testng.internal.TestMethodWorker.invokeTestMethods(TestMethodWorker.java:129)
	at org.testng.internal.TestMethodWorker.run(TestMethodWorker.java:112)
	at org.testng.TestRunner.privateRun(TestRunner.java:782)
	at org.testng.TestRunner.run(TestRunner.java:632)
	at org.testng.SuiteRunner.runTest(SuiteRunner.java:366)
	at org.testng.SuiteRunner.runSequentially(SuiteRunner.java:361)
	at org.testng.SuiteRunner.privateRun(SuiteRunner.java:319)
	at org.testng.SuiteRunner.run(SuiteRunner.java:268)
	at org.testng.SuiteRunnerWorker.runSuite(SuiteRunnerWorker.java:52)
	at org.testng.SuiteRunnerWorker.run(SuiteRunnerWorker.java:86)
	at org.testng.TestNG.runSuitesSequentially(TestNG.java:1244)
	at org.testng.TestNG.runSuitesLocally(TestNG.java:1169)
	at org.testng.TestNG.run(TestNG.java:1064)
	at org.testng.remote.AbstractRemoteTestNG.run(AbstractRemoteTestNG.java:132)
	at org.testng.remote.RemoteTestNG.initAndRun(RemoteTestNG.java:236)
	at org.testng.remote.RemoteTestNG.main(RemoteTestNG.java:81)
Caused by: java.lang.NullPointerException
	at dataProviderFactorry.ExcelDataProvider.getRows(ExcelDataProvider.java:47)
	at testcases.LoginTestWithDataProvider.getDataFromsource(LoginTestWithDataProvider.java:115)
	at sun.reflect.NativeMethodAccessorImpl.invoke0(Native Method)
	at sun.reflect.NativeMethodAccessorImpl.invoke(Unknown Source)
	at sun.reflect.DelegatingMethodAccessorImpl.invoke(Unknown Source)
	at java.lang.reflect.Method.invoke(Unknown Source)
	at org.testng.internal.MethodInvocationHelper.invokeMethod(MethodInvocationHelper.java:86)
	at org.testng.internal.MethodInvocationHelper.invokeDataProvider(MethodInvocationHelper.java:137)
	... 20 more
]]>
            </full-stacktrace>
          </exception> <!-- java.lang.RuntimeException -->
          <reporter-output>
          </reporter-output>
        </test-method> <!-- userManagement -->
        <test-method status="PASS" signature="CloseSessons()[pri:0, instance:testcases.LoginTestWithDataProvider@3532ec19]" name="CloseSessons" is-config="true" duration-ms="687" started-at="2020-02-14T01:08:07Z" finished-at="2020-02-14T01:08:08Z">
          <reporter-output>
          </reporter-output>
        </test-method> <!-- CloseSessons -->
      </class> <!-- testcases.LoginTestWithDataProvider -->
    </test> <!-- Default test -->
  </suite> <!-- Default suite -->
</testng-results>
